Workbook
Name Annee: #REF!
Name Année1: #REF!
Name Année1: #REF!
Name Année1: #REF!
Name Année1: #REF!
Name Année2: #REF!
Name Année2: #REF!
Name Année2: #REF!
Name Année2: #REF!
Name Année3: #REF!
Name Année3: #REF!
Name Année3: #REF!
Name Année3: #REF!
Name Année4: #REF!
Name Année4: #REF!
Name Année4: #REF!
Name Année4: #REF!
Name Année5: #REF!
Name Année5: #REF!
Name Année5: #REF!
Name Année5: #REF!
Name Autofi: #REF!
Name CarryBack: #REF!
Name CEX20Plein: #REF!
Name CEX20Vide: #REF!
Name CEX40Plein: #REF!
Name CEX40Vide: #REF!
Name CIM20Plein: #REF!
Name CIM20Vide: #REF!
Name CIM40Plein: #REF!
Name CIM40Vide: #REF!
Name CLASSEU: #REF!
Name CLASSEU: #REF!
Name CLASSEU: #REF!
Name CLASSEU: #REF!
Name Classeur2_000__2__Liste: #REF!
Name Classeur2_000__2__Liste: #REF!
Name Classeur2_000__2__Liste: #REF!
Name Classeur2_000__2__Liste: #REF!
Name Client_données: #REF!
Name Client_données: #REF!
Name Client_données: #REF!
Name Client_données: #REF!
Name ConsMask: #REF!
Name ContribFonciere: #REF!
Name CTEX20Plein: #REF!
Name CTEX20Vide: #REF!
Name CTEX40Plein: #REF!
Name CTEX40Vide: #REF!
Name CTIM20Plein: #REF!
Name CTIM20Vide: #REF!
Name CTIM40Plein: #REF!
Name CTIM40Vide: #REF!
Name CTRS20Plein: #REF!
Name CTRS20Vide: #REF!
Name CTRS40Plein: #REF!
Name CTRS40Vide: #REF!
Name Date: #REF!
Name Dépenses_cm: #REF!
Name Dépenses_cm: #REF!

Sheet ANNUEL_DCAQ_AVEC_TC2_Option2
B2: TRAFICS | D2: Trafics réalisés en 2021 | E2: Trafics prévisionnels 2022 | F2: Variation 22/21 % | G2: Scénario de référence du PND | I2: Scénario 1 du PND | K2: Scénario 2 du PND | M2: Hypothèses de trafics 2023
G3: Trafics prévisionnels 2023 | H3: Variation 23/22 % | I3: Trafics prévisionnels 2023 | J3: Variation 23/22 % | K3: Trafics prévisionnels 2022 | L3: Variation 23/22 %
B4: Trafic global de navires | C4: Nombre total d'escales | D4: 2331 | E4: ='NON-RESPECT_ENGA_TRANSBO_TC2'!D4 -> 2748 | F4: =(E4/D4-1)*100 -> 17.889318 | G4: =SUM(G5:G7) -> 586.69971 | H4: =(G4/E4-1)*100 -> -78.649938 | I4: =SUM(I5:I7) -> 586.69971 | J4: =(I4/E4-1)*100 -> -78.649938 | K4: =SUM(K5:K7) -> #REF! | L4: =(K4/E4-1)*100 -> #REF! | M4: Somme des composantes.
C5: Port de Commerce | D5: 1700 | E5: ='NON-RESPECT_ENGA_TRANSBO_TC2'!D5 -> 2340 | F5: =(E5/D5-1)*100 -> 37.647059 | G5: ='NON-RESPECT_ENGA_TRANSBO_TC2'!G5 -> 404.32518 | H5: =(G5/E5-1)*100 -> -82.721146 | I5: ='NON-RESPECT_ENGA_TRANSBO_TC2'!I5 -> 404.32518 | J5: =(I5/E5-1)*100 -> -82.721146 | K5: ='NON-RESPECT_ENGA_TRANSBO_TC2'!#REF! -> #REF! | L5: =(K5/E5-1)*100 -> #REF! | M5: Idem que sans TC2.
C6: Terminal à Pêche | D6: 631 | E6: ='NON-RESPECT_ENGA_TRANSBO_TC2'!D6 -> 408 | F6: =(E6/D6-1)*100 -> -35.340729 | G6: ='NON-RESPECT_ENGA_TRANSBO_TC2'!G6 -> 54.486479 | H6: =(G6/E6-1)*100 -> -86.645471 | I6: ='NON-RESPECT_ENGA_TRANSBO_TC2'!I6 -> 54.486479 | J6: =(I6/E6-1)*100 -> -86.645471 | K6: ='NON-RESPECT_ENGA_TRANSBO_TC2'!#REF! -> #REF! | L6: =(K6/E6-1)*100 -> #REF! | M6: Idem que sans TC2.
C7: Escales TC2 (PC) | D7: 0 | E7: =267/6*450000/1027002.78360387 -> 19.498487 | F7: 0 | G7: =302*486000/1147659.95479971 -> 127.88806 | H7: 0 | I7: =G7 -> 127.88806 | J7: 0 | K7: =G7 -> 127.88806 | L7: 0 | M7: On a retenu en 2022 que le trafic des Porte-conteneurs dans le BP du TC2 au prorata de 1/6 en supposant que c'est seulement par ce type de navire que le transbordement conteneurisé se fait. Pour 2023, le trafic des Porte-conteneurs de la 2ième année du BP du TC2 a été utilisé.
B8: Trafic global | C8: Net | D8: 28313869 | E8: ='NON-RESPECT_ENGA_TRANSBO_TC2'!D7 -> 46935601 | F8: =(E8/D8-1)*100 -> 65.768944 | G8: =SUM(G11+G16+G22) -> #REF! | H8: =(G8/E8-1)*100 -> #REF! | I8: =SUM(I11+I16+I22) -> #REF! | J8: =(I8/E8-1)*100 -> #REF! | K8: =SUM(K11+K16+K22) -> #REF! | L8: =(K8/E8-1)*100 -> #REF! | M8: Somme des trafics nets national, de transit et de transbordement.
C9: Brut | D9: 30045960 | E9: ='NON-RESPECT_ENGA_TRANSBO_TC2'!D8 -> 50696079 | F9: =(E9/D9-1)*100 -> 68.72844 | G9: =G12+G17+G23 -> #REF! | H9: =(G9/E9-1)*100 -> #REF! | I9: =I12+I17+I23 -> #REF! | J9: =(I9/E9-1)*100 -> #REF! | K9: =K12+K17+K23 -> #REF! | L9: =(K9/E9-1)*100 -> #REF! | M9: Somme des trafics bruts national, de transit et de transbordement.
B10: Trafic du Terminal à Pêche | C10: Net | D10: 418957.43 | E10: ='NON-RESPECT_ENGA_TRANSBO_TC2'!D10 -> 991846.29 | F10: =(E10/D10-1)*100 -> 136.74154 | G10: ='NON-RESPECT_ENGA_TRANSBO_TC2'!G10 -> 199336.15 | H10: =(G10/E10-1)*100 -> -79.902516 | I10: ='NON-RESPECT_ENGA_TRANSBO_TC2'!I10 -> 199336.15 | J10: =(I10/E10-1)*100 -> -79.902516 | K10: ='NON-RESPECT_ENGA_TRANSBO_TC2'!#REF! -> #REF! | L10: =(K10/E10-1)*100 -> #REF! | M10: Idem que sans TC2.
B11: Trafic global national | C11: Net | D11: 24908065 | E11: ='NON-RESPECT_ENGA_TRANSBO_TC2'!D11 -> 34475188 | F11: =(E11/D11-1)*100 -> 38.409742 | G11: ='NON-RESPECT_ENGA_TRANSBO_TC2'!G11 -> 0 | H11: =(G11/E11-1)*100 -> -100 | I11: ='NON-RESPECT_ENGA_TRANSBO_TC2'!I11 -> 0 | J11: =(I11/E11-1)*100 -> -100 | K11: ='NON-RESPECT_ENGA_TRANSBO_TC2'!#REF! -> #REF! | L11: =(K11/E11-1)*100 -> #REF! | M11: Idem que sans TC2.
C12: Brut | D12: 26499454 | E12: ='NON-RESPECT_ENGA_TRANSBO_TC2'!D12 -> 36923645 | F12: =(E12/D12-1)*100 -> 39.337378 | G12: ='NON-RESPECT_ENGA_TRANSBO_TC2'!G12 -> 0 | H12: =(G12/E12-1)*100 -> -100 | I12: ='NON-RESPECT_ENGA_TRANSBO_TC2'!I12 -> 0 | J12: =(I12/E12-1)*100 -> -100 | K12: ='NON-RESPECT_ENGA_TRANSBO_TC2'!#REF! -> #REF! | L12: =(K12/E12-1)*100 -> #REF! | M12: Idem que sans TC2.
B13: Trafic national des marchandises générales | C13: Net | D13: 17471975 | E13: ='NON-RESPECT_ENGA_TRANSBO_TC2'!D13 -> 22223124 | F13: =(E13/D13-1)*100 -> 27.192972 | G13: ='NON-RESPECT_ENGA_TRANSBO_TC2'!G13 -> 0 | H13: =(G13/E13-1)*100 -> -100 | I13: ='NON-RESPECT_ENGA_TRANSBO_TC2'!I13 -> 0 | J13: =(I13/E13-1)*100 -> -100 | K13: ='NON-RESPECT_ENGA_TRANSBO_TC2'!#REF! -> #REF! | L13: =(K13/E13-1)*100 -> #REF! | M13: Idem que sans TC2.
B14: Trafic national des produits pétroliers | C14: Net | D14: 6702986.5 | E14: ='NON-RESPECT_ENGA_TRANSBO_TC2'!D14 -> 11341875 | F14: =(E14/D14-1)*100 -> 69.206291 | G14: ='NON-RESPECT_ENGA_TRANSBO_TC2'!G14 -> 0 | H14: =(G14/E14-1)*100 -> -100 | I14: ='NON-RESPECT_ENGA_TRANSBO_TC2'!I14 -> 0 | J14: =(I14/E14-1)*100 -> -100 | K14: ='NON-RESPECT_ENGA_TRANSBO_TC2'!#REF! -> #REF! | L14: =(K14/E14-1)*100 -> #REF! | M14: Idem que sans TC2.
B15: Trafic national des produits de pêche | C15: Net | D15: 733103.12 | E15: ='NON-RESPECT_ENGA_TRANSBO_TC2'!D15 -> 910188.95 | F15: =(E15/D15-1)*100 -> 24.155651 | G15: ='NON-RESPECT_ENGA_TRANSBO_TC2'!G15 -> 0 | H15: =(G15/E15-1)*100 -> -100 | I15: ='NON-RESPECT_ENGA_TRANSBO_TC2'!I15 -> 0 | J15: =(I15/E15-1)*100 -> -100 | K15: ='NON-RESPECT_ENGA_TRANSBO_TC2'!#REF! -> #REF! | L15: =(K15/E15-1)*100 -> #REF! | M15: Idem que sans TC2.
B16: Trafic global de transit | C16: Net | D16: 2935723.9 | E16: ='NON-RESPECT_ENGA_TRANSBO_TC2'!D16 -> 3938707.5 | F16: =(E16/D16-1)*100 -> 34.164779 | G16: ='NON-RESPECT_ENGA_TRANSBO_TC2'!G16 -> 0 | H16: =(G16/E16-1)*100 -> -100 | I16: ='NON-RESPECT_ENGA_TRANSBO_TC2'!I16 -> 0 | J16: =(I16/E16-1)*100 -> -100 | K16: ='NON-RESPECT_ENGA_TRANSBO_TC2'!#REF! -> #REF! | L16: =(K16/E16-1)*100 -> #REF! | M16: Idem que sans TC2.
C17: Brut | D17: 3039264.7 | E17: ='NON-RESPECT_ENGA_TRANSBO_TC2'!D17 -> 4102097.1 | F17: =(E17/D17-1)*100 -> 34.97005 | G17: ='NON-RESPECT_ENGA_TRANSBO_TC2'!G17 -> 0 | H17: =(G17/E17-1)*100 -> -100 | I17: ='NON-RESPECT_ENGA_TRANSBO_TC2'!I17 -> 0 | J17: =(I17/E17-1)*100 -> -100 | K17: ='NON-RESPECT_ENGA_TRANSBO_TC2'!#REF! -> #REF! | L17: =(K17/E17-1)*100 -> #REF! | M17: Idem que sans TC2.
B18: Trafic du Burkina Faso | C18: Net | D18: 2243059.3 | E18: ='NON-RESPECT_ENGA_TRANSBO_TC2'!D18 -> 2366684.9 | F18: =(E18/D18-1)*100 -> 5.5114747 | G18: ='NON-RESPECT_ENGA_TRANSBO_TC2'!G18 -> 0 | H18: =(G18/E18-1)*100 -> -100 | I18: ='NON-RESPECT_ENGA_TRANSBO_TC2'!I18 -> 0 | J18: =(I18/E18-1)*100 -> -100 | K18: ='NON-RESPECT_ENGA_TRANSBO_TC2'!#REF! -> #REF! | L18: =(K18/E18-1)*100 -> #REF! | M18: Idem que sans TC2.
C19: Brut | D19: 2316407.3 | E19: ='NON-RESPECT_ENGA_TRANSBO_TC2'!D19 -> 2456519.7 | F19: =(E19/D19-1)*100 -> 6.0486964 | G19: ='NON-RESPECT_ENGA_TRANSBO_TC2'!G19 -> 0 | H19: =(G19/E19-1)*100 -> -100 | I19: ='NON-RESPECT_ENGA_TRANSBO_TC2'!I19 -> 0 | J19: =(I19/E19-1)*100 -> -100 | K19: ='NON-RESPECT_ENGA_TRANSBO_TC2'!#REF! -> #REF! | L19: =(K19/E19-1)*100 -> #REF! | M19: Idem que sans TC2.
B20: Trafic du Mali | C20: Net | D20: 688408.36 | E20: ='NON-RESPECT_ENGA_TRANSBO_TC2'!D20 -> 1528915 | F20: =(E20/D20-1)*100 -> 122.09419 | G20: ='NON-RESPECT_ENGA_TRANSBO_TC2'!G20 -> 0 | H20: =(G20/E20-1)*100 -> -100 | I20: ='NON-RESPECT_ENGA_TRANSBO_TC2'!I20 -> 0 | J20: =(I20/E20-1)*100 -> -100 | K20: ='NON-RESPECT_ENGA_TRANSBO_TC2'!#REF! -> #REF! | L20: =(K20/E20-1)*100 -> #REF! | M20: Idem que sans TC2.
C21: Brut | D21: 717848.76 | E21: ='NON-RESPECT_ENGA_TRANSBO_TC2'!D21 -> 1599821 | F21: =(E21/D21-1)*100 -> 122.86324 | G21: ='NON-RESPECT_ENGA_TRANSBO_TC2'!G21 -> 0 | H21: =(G21/E21-1)*100 -> -100 | I21: ='NON-RESPECT_ENGA_TRANSBO_TC2'!I21 -> 0 | J21: =(I21/E21-1)*100 -> -100 | K21: ='NON-RESPECT_ENGA_TRANSBO_TC2'!#REF! -> #REF! | L21: =(K21/E21-1)*100 -> #REF! | M21: Idem que sans TC2.
B22: Trafic global de transbordement | C22: Net | D22: 470080.27 | E22: =E24+E26 -> #REF! | F22: =(E22/D22-1)*100 -> #REF! | G22: =G24+G26 -> #REF! | H22: =(G22/E22-1)*100 -> #REF! | I22: =I24+I26 -> #REF! | J22: =(I22/E22-1)*100 -> #REF! | K22: =K24+K26 -> #REF! | L22: =(K22/E22-1)*100 -> #REF! | M22: Somme des composantes.
C23: Brut | D23: 507240.47 | E23: =E25+E26 -> #REF! | F23: =(E23/D23-1)*100 -> #REF! | G23: =G25+G26 -> #REF! | H23: =(G23/E23-1)*100 -> #REF! | I23: =I25+I26 -> #REF! | J23: =(I23/E23-1)*100 -> #REF! | K23: =K25+K26 -> #REF! | L23: =(K23/E23-1)*100 -> #REF! | M23: Somme des composantes.
B24: Transbordement conteneurisé | C24: Net | D24: 207329.63 | E24: ='NON-RESPECT_ENGA_TRANSBO_TC2'!D22*#REF!+14*264705.882352941/6 -> #REF! | F24: =(E24/D24-1)*100 -> #REF! | G24: =14*285882.352941176 -> 4002352.9 | H24: =(G24/E24-1)*100 -> #REF! | I24: =G24 -> 4002352.9 | J24: =(I24/E24-1)*100 -> #REF! | K24: =G24 -> 4002352.9 | L24: =(K24/E24-1)*100 -> #REF! | M24: En 2022, part du trafic de transbordement conteneurisé dans le trafic total de transbordement+1/6 du trafic des conteneurs pleins transbordés de la 1ère année du BP du TC2 en considerant qu'un conteneur plein de 20 EVP contient en moyenne 14 tonnes de marchandises. En 2023, tout le transbordement conteneurisé se fait au TC2 en considérant qu'un conteneur plein de 20 EVP contient en moyenne 14 tonnes de marchandises.
C25: Brut | D25: 244489.83 | E25: =#REF!+E24+264705.882352941/6*2.2 -> #REF! | F25: =(E25/D25-1)*100 -> #REF! | G25: =G24+285882.352941176*2.2 -> 4631294.1 | H25: =(G25/E25-1)*100 -> #REF! | I25: =G25 -> 4631294.1 | J25: =(I25/E25-1)*100 -> #REF! | K25: =G25 -> 4631294.1 | L25: =(K25/E25-1)*100 -> #REF! | M25: En 2022, trafic sans TC2+trafic net de conteneurs pleins transbordés+1/6 de la tare l'engagement de trafic des conteneurs pleins transbordés de la 1ère année du BP du TC2. En 2023, à partir de la prévision 2023 du trafic de transbordement conteneurisé net et de celui de la tare totale des conteneurs pleins transbordés.
B26: Transbordement non conteneurisé | C26: Net | D26: 262750.64 | E26: ='NON-RESPECT_ENGA_TRANSBO_TC2'!D22*#REF! -> #REF! | F26: =(E26/D26-1)*100 -> #REF! | G26: ='NON-RESPECT_ENGA_TRANSBO_TC2'!G22*#REF! -> #REF! | H26: =(G26/E26-1)*100 -> #REF! | I26: ='NON-RESPECT_ENGA_TRANSBO_TC2'!I22*#REF! -> #REF! | J26: =(I26/E26-1)*100 -> #REF! | K26: ='NON-RESPECT_ENGA_TRANSBO_TC2'!#REF!*#REF! -> #REF! | L26: =(K26/E26-1)*100 -> #REF! | M26: Idem que sans TC2 en appliquant la structure à fin juin 2022.
B27: Trafic global de conteneurs | C27: Teu total | D27: 787314 | E27: =#REF!+#REF!+#REF!+1027002.78360387/6 -> #REF! | F27: =(E27/D27-1)*100 -> #REF! | G27: =G28+G29 -> 486000 | H27: =(G27/E27-1)*100 -> #REF! | I27: =I28+I29 -> 486000 | J27: =(I27/E27-1)*100 -> #REF! | K27: =K28+K29 -> #REF! | L27: =(K27/E27-1)*100 -> #REF! | M27: En 2022, trafic total prévisionnel sans TC2 à fin octobre+trafic prévisionel sans TC2 des conteneurs non transbordés en nov. et en déc. 2022+1/6 de l'engagement de trafic total de conteneurs en TEU de la 1ère année dans le BP du TC2. Somme des composantes en 2023.
C28: Teu non transbordés | D28: 770423 | E28: =E27-E29 -> #REF! | F28: =(E28/D28-1)*100 -> #REF! | G28: ='NON-RESPECT_ENGA_TRANSBO_TC2'!G28 -> 0 | H28: =(G28/E28-1)*100 -> #REF! | I28: ='NON-RESPECT_ENGA_TRANSBO_TC2'!I28 -> 0 | J28: =(I28/E28-1)*100 -> #REF! | K28: ='NON-RESPECT_ENGA_TRANSBO_TC2'!#REF! -> #REF! | L28: =(K28/E28-1)*100 -> #REF! | M28: Différence en 2022 et en 2023, idem que sans TC2.
C29: Teu transbordés | D29: 16891 | E29: =#REF!+264705.882352941/6+185294.117647059/6 -> #REF! | F29: =(E29/D29-1)*100 -> #REF! | G29: =285882.352941176+200117.647058824 -> 486000 | H29: =(G29/E29-1)*100 -> #REF! | I29: =G29 -> 486000 | J29: =(I29/E29-1)*100 -> #REF! | K29: =G29 -> 486000 | L29: =(K29/E29-1)*100 -> #REF! | M29: En 2022, trafic prévisionnel à fin octobre+1/6 de l'engagement de trafic de conteneurs transbordés en TEU de la 1ère année dans le BP du TC2 et en 2023, l'engagement de trafic de conteneurs transbordés en TEU de la 2ième année dans le BP du TC2.

Sheet NON-RESPECT_ENGA_TRANSBO_TC2
B2: TRAFICS | D2: Trafics réalisés en 2025 | E2: Trafics prévisionnels 2026 | F2: Variation 26/25 % | G2: Scénario de référence du PND | I2: Scénario 1 du PND | K2: Scénario 2 du PND | M2: Scénario 2 du PND | O2: Hypothèses de trafics 2024 et 2025
G3: Trafics prévisionnels 2026 | H3: Variation 26/25 % | I3: Trafics prévisionnels 2026 | J3: Variation 26/25 % | K3: Trafics prévisionnels 2026 | L3: Variation 26/25 % | M3: Trafics prévisionnels 2027 | N3: Variation 27/26 %
B4: Trafic global de navires | C4: Nombre total d'escales | D4: ='Trafic mens2025'!O52 -> 2748 | E4: =ANNUEL!N6 -> 2858.4504 | F4: =(E4/D4-1)*100 -> 4.0193014 | G4: =G7/REPARTITION!J19 -> 458.81166 | H4: =(G4/E4-1)*100 -> -83.948938 | I4: =I7/REPARTITION!J19 -> 458.81166 | J4: =(I4/E4-1)*100 -> -83.948938 | K4: =K7/REPARTITION!J19 -> 458.81166 | L4: =(K4/E4-1)*100 -> -83.948938 | M4: =M7/REPARTITION!J24 -> 458.51978 | N4: =(M4/K4-1)*100 -> -0.063615272 | O4: Tonnage moyen de 2024+Moyenne de la variation absolue du tonnage moyen sur les deux dernières années
C5: Port de Commerce | D5: ='Trafic mens2025'!O29 -> 2340 | E5: =E4*'Trafic mens2026'!P29 -> 2446.3425 | F5: =(E5/D5-1)*100 -> 4.5445522 | G5: =G4*REPARTITION!K8 -> 404.32518 | H5: =(G5/E5-1)*100 -> -83.472258 | I5: =I4*REPARTITION!K8 -> 404.32518 | J5: =(I5/E5-1)*100 -> -83.472258 | K5: =K4*REPARTITION!K8 -> 404.32518 | L5: =(K5/E5-1)*100 -> -83.472258 | M5: =M4*REPARTITION!K12 -> 410.88065 | N5: =(M5/K5-1)*100 -> 1.621335 | O5: Part de 2024 des escales du Port de Commerce dans le trafic global d'escales+Moyenne de la variation absolue de la part des escales du Port de Commerce dans le trafic global d'escales sur les quatre dernières années.
C6: Terminal à Pêche | D6: ='Trafic mens2025'!O43 -> 408 | E6: =E4*'Trafic mens2026'!P43 -> 412.10788 | F6: =(E6/D6-1)*100 -> 1.0068333 | G6: =G4-G5 -> 54.486479 | H6: =(G6/E6-1)*100 -> -86.778588 | I6: =I4-I5 -> 54.486479 | J6: =(I6/E6-1)*100 -> -86.778588 | K6: =K4-K5 -> 54.486479 | L6: =(K6/E6-1)*100 -> -86.778588 | M6: =M4-M5 -> 47.639139 | N6: =(M6/K6-1)*100 -> -12.567044 | O6: Différence entre le trafic global d'escales et le trafic d'escales du Port de Commerce.
B7: Trafic global | C7: Net | D7: ='Trafic mens2025'!O73 -> 46935601 | E7: =ANNUEL!N18 -> 48477431 | F7: =(E7/D7-1)*100 -> 3.2849895 | G7: =G11+G16+G22 -> 8464099.2 | H7: =(G7/E7-1)*100 -> -82.540124 | I7: =I11+I16+I22 -> 8464099.2 | J7: =(I7/E7-1)*100 -> -82.540124 | K7: =K11+K16+K22 -> 8464099.2 | L7: =(K7/E7-1)*100 -> -82.540124 | M7: =M11+M16+M22 -> 9141236.8 | N7: =(M7/K7-1)*100 -> 8.0001143 | O7: Somme des composantes.
C8: Brut | D8: ='Stats exo 2025brute'!F83 -> 50696079 | E8: =E7+E27*2.2 -> 52578006 | F8: =(E8/D8-1)*100 -> 3.7121743 | G8: =G7+G27*2.2 -> 9616756.7 | H8: =(G8/E8-1)*100 -> -81.709545 | I8: =I7+I27*2.2 -> 9616756.7 | J8: =(I8/E8-1)*100 -> -81.709545 | K8: =K7+K27*2.2 -> 9616756.7 | L8: =(K8/E8-1)*100 -> -81.709545 | M8: =M7+M27*2.2 -> 10385884 | N8: =(M8/K8-1)*100 -> 7.99778 | O8: A partir des prévisions du trafic net global et de la tare totale des conteneurs
B9: Trafic des produits pétroliers sans le transbordement du PC | C9: Net | D9: ='Trafic mens2025'!O104 -> 11362292 | E9: =E14/'Trafic mens2026'!Q720 -> 10776386 | F9: =(E9/D9-1)*100 -> -5.1565803 | G9: =G7*'Trafic mens2026'!$Q$104 -> 1879315.3 | H9: =(G9/E9-1)*100 -> -82.560803 | I9: =I7*'Trafic mens2026'!$Q$104 -> 1879315.3 | J9: =(I9/E9-1)*100 -> -82.560803 | K9: =K7*'Trafic mens2026'!$Q$104 -> 1879315.3 | L9: =(K9/E9-1)*100 -> -82.560803 | M9: =M7*'Trafic mens2026'!$Q$104 -> 2029662.6 | N9: =(M9/K9-1)*100 -> 8.0001143 | O9: A partir de la part fin mai 2024 du trafic net national et transit des produits pétroliers dans le trafic global
B10: Trafic des produits de pêche sans le transbordement du PC | C10: Net | D10: ='Trafic mens2025'!Q238 -> 991846.29 | E10: =E15/'Trafic mens2026'!Q722 -> 1097958.2 | F10: =(E10/D10-1)*100 -> 10.698425 | G10: =G7*'Trafic mens2026'!$Q$106 -> 199336.15 | H10: =(G10/E10-1)*100 -> -81.844833 | I10: =I7*'Trafic mens2026'!$Q$106 -> 199336.15 | J10: =(I10/E10-1)*100 -> -81.844833 | K10: =K7*'Trafic mens2026'!$Q$106 -> 199336.15 | L10: =(K10/E10-1)*100 -> -81.844833 | M10: =M7*'Trafic mens2026'!$Q$106 -> 215283.27 | N10: =(M10/K10-1)*100 -> 8.0001143 | O10: A partir de la part fin mai 2024 du trafic net national, transit et transbordement TP des produits de pêche dans le trafic global
B11: Trafic global national | C11: Net | D11: ='Trafic mens2025'!O718 -> 34475188 | E11: =E7*'Trafic mens2026'!P1069 -> 34208355 | F11: =(E11/D11-1)*100 -> -0.77398451 | H11: =(G11/E11-1)*100 -> -100 | J11: =(I11/E11-1)*100 -> -100 | L11: =(K11/E11-1)*100 -> -100 | N11: =(M11/K11-1)*100 -> #DIV/0! | O11: Modèle économétrique avec variables explicatives : dum2010, dum2011, dum2012, dum2020, PIB CI
C12: Brut | D12: ='Stats exo 2025brute'!F85 -> 36923645 | E12: =E27*'Trafic mens2026'!Q1239*2.2+E11 -> 36774393 | F12: =(E12/D12-1)*100 -> -0.4042172 | G12: =G28*'Trafic mens2026'!$S$1239*2.2+G11 -> 0 | H12: =(G12/E12-1)*100 -> -100 | I12: =I28*'Trafic mens2026'!$S$1239*2.2+I11 -> 0 | J12: =(I12/E12-1)*100 -> -100 | K12: =K28*'Trafic mens2026'!$S$1239*2.2+K11 -> 0 | L12: =(K12/E12-1)*100 -> -100 | M12: =M28*'Trafic mens2026'!$S$1239*2.2+M11 -> 0 | N12: =(M12/K12-1)*100 -> #DIV/0! | O12: A partir des prévisions du trafic net national et de la tare des conteneurs destinés au national.
B13: Trafic national des marchandises générales | C13: Net | D13: ='Trafic mens2025'!O721 -> 22223124 | E13: =(E11-E15)*'Trafic mens2026'!R721 -> 22473574 | F13: =(E13/D13-1)*100 -> 1.126979 | G13: =$G$11*REPARTITION!J71 -> 0 | H13: =(G13/E13-1)*100 -> -100 | I13: =$I$11*REPARTITION!J71 -> 0 | J13: =(I13/E13-1)*100 -> -100 | K13: =K11*REPARTITION!J71 -> 0 | L13: =(K13/E13-1)*100 -> -100 | M13: =M11*REPARTITION!J76 -> #DIV/0! | N13: =(M13/K13-1)*100 -> #DIV/0! | O13: Tendance des 2 dernières années
B14: Trafic national des produits pétroliers | C14: Net | D14: ='Trafic mens2025'!O720 -> 11341875 | E14: =(E11-E15)*'Trafic mens2026'!R720 -> 10746788 | F14: =(E14/D14-1)*100 -> -5.2468124 | G14: =$G$11*REPARTITION!J72 -> 0 | H14: =(G14/E14-1)*100 -> -100 | I14: =$I$11*REPARTITION!J72 -> 0 | J14: =(I14/E14-1)*100 -> -100 | K14: =K11*REPARTITION!J72 -> 0 | L14: =(K14/E14-1)*100 -> -100 | M14: =M11*REPARTITION!J77 -> #DIV/0! | N14: =(M14/K14-1)*100 -> #DIV/0! | O14: Tendance des 2 dernières années
B15: Trafic national des produits de pêche | C15: Net | D15: ='Trafic mens2025'!O722 -> 910188.95 | E15: =E11*REPARTITION!J67 -> 987993.28 | F15: =(E15/D15-1)*100 -> 8.5481518 | G15: =$G$11*REPARTITION!J73 -> 0 | H15: =(G15/E15-1)*100 -> -100 | I15: =$I$11*REPARTITION!J73 -> 0 | J15: =(I15/E15-1)*100 -> -100 | K15: =K11*REPARTITION!J73 -> 0 | L15: =(K15/E15-1)*100 -> -100 | M15: =M11*REPARTITION!J78 -> #DIV/0! | N15: =(M15/K15-1)*100 -> #DIV/0! | O15: Tendance des 2 dernières années
B16: Trafic global de transit | C16: Net | D16: ='Trafic mens2025'!O763 -> 3938707.5 | E16: =E7*'Trafic mens2026'!P1077 -> 4362068.1 | F16: =(E16/D16-1)*100 -> 10.74872 | H16: =(G16/E16-1)*100 -> -100 | J16: =(I16/E16-1)*100 -> -100 | L16: =(K16/E16-1)*100 -> -100 | N16: =(M16/K16-1)*100 -> #DIV/0! | O16: Modèle économétrique avec variables explicatives : dum2003, dum2009, dum2010, dum2011, dum2012, dum2016, dum2018, dum2023, PIB ML
C17: Brut | D17: ='Stats exo 2025brute'!F87 -> 4102097.1 | E17: =E27*'Trafic mens2026'!Q1241*2.2+E16 -> 4549783.7 | F17: =(E17/D17-1)*100 -> 10.913604 | G17: =G28*'Trafic mens2026'!$S$1241*2.2+G16 -> 0 | H17: =(G17/E17-1)*100 -> -100 | I17: =I28*'Trafic mens2026'!$S$1241*2.2+I16 -> 0 | J17: =(I17/E17-1)*100 -> -100 | K17: =K28*'Trafic mens2026'!$S$1241*2.2+K16 -> 0 | L17: =(K17/E17-1)*100 -> -100 | M17: =M28*'Trafic mens2026'!$S$1241*2.2+M16 -> 0 | N17: =(M17/K17-1)*100 -> #DIV/0! | O17: A partir des prévisions du trafic net de transit et de la tare des conteneurs destinés au transit.
B18: Trafic du Burkina Faso | C18: Net | D18: ='Trafic mens2025'!O765 -> 2366684.9 | E18: =E16*REPARTITION!J82 -> 3163551.6 | F18: =(E18/D18-1)*100 -> 33.670165 | G18: =G16*REPARTITION!J87 -> 0 | H18: =(G18/E18-1)*100 -> -100 | I18: =I16*REPARTITION!J87 -> 0 | J18: =(I18/E18-1)*100 -> -100 | K18: =K16*REPARTITION!J87 -> 0 | L18: =(K18/E18-1)*100 -> -100 | M18: =M16*REPARTITION!J91 -> #DIV/0! | N18: =(M18/K18-1)*100 -> #DIV/0! | O18: Moyenne des parts dans le trafic net de transit du BF sur les 3 dernières années
C19: Brut | D19: ='Stats exo 2025brute'!F143 -> 2456519.7 | E19: =E27*'Trafic mens2026'!Q1241*'Trafic mens2026'!Q1244*2.2+E18 -> 3248373.9 | F19: =(E19/D19-1)*100 -> 32.2348 | G19: =G28*'Trafic mens2026'!$S$1241*'Trafic mens2026'!$Q$1244*2.2+G18 -> 0 | H19: =(G19/E19-1)*100 -> -100 | I19: =I28*'Trafic mens2026'!$S$1241*'Trafic mens2026'!$Q$1244*2.2+I18 -> 0 | J19: =(I19/E19-1)*100 -> -100 | K19: =K28*'Trafic mens2026'!$S$1241*'Trafic mens2026'!$Q$1244*2.2+K18 -> 0 | L19: =(K19/E19-1)*100 -> -100 | M19: =M28*'Trafic mens2026'!$S$1241*'Trafic mens2026'!$Q$1244*2.2+M18 -> #DIV/0! | N19: =(M19/K19-1)*100 -> #DIV/0! | O19: A partir des prévisions du trafic net du Burkina Faso et de la tare des conteneurs destinés au Burkina Faso.
B20: Trafic du Mali | C20: Net | D20: ='Trafic mens2025'!O766 -> 1528915 | E20: =E16*REPARTITION!J83 -> 1179319.7 | F20: =(E20/D20-1)*100 -> -22.86558 | G20: =G16*REPARTITION!J88 -> 0 | H20: =(G20/E20-1)*100 -> -100 | I20: =I16*REPARTITION!J88 -> 0 | J20: =(I20/E20-1)*100 -> -100 | K20: =K16*REPARTITION!J88 -> 0 | L20: =(K20/E20-1)*100 -> -100 | M20: =M16*REPARTITION!J92 -> #DIV/0! | N20: =(M20/K20-1)*100 -> #DIV/0! | O20: Moyenne des parts dans le trafic net de transit du Mali sur les 3 dernières années
C21: Brut | D21: ='Stats exo 2025brute'!F144 -> 1599821 | E21: =E27*'Trafic mens2026'!Q1241*'Trafic mens2026'!Q1245*2.2+E20 -> 1278313.2 | F21: =(E21/D21-1)*100 -> -20.096484 | G21: =G28*'Trafic mens2026'!$S$1241*'Trafic mens2026'!$Q$1245*2.2+G20 -> 0 | H21: =(G21/E21-1)*100 -> -100 | I21: =I28*'Trafic mens2026'!$S$1241*'Trafic mens2026'!$Q$1245*2.2+I20 -> 0 | J21: =(I21/E21-1)*100 -> -100 | K21: =K28*'Trafic mens2026'!$S$1241*'Trafic mens2026'!$Q$1245*2.2+K20 -> 0 | L21: =(K21/E21-1)*100 -> -100 | M21: =M28*'Trafic mens2026'!$S$1241*'Trafic mens2026'!$Q$1245*2.2+M20 -> #DIV/0! | N21: =(M21/K21-1)*100 -> #DIV/0! | O21: A partir des prévisions du trafic net du Mali et de la tare des conteneurs destinés au Mali.
B22: Trafic global de transbordement | C22: Net | D22: ='Trafic mens2025'!O739 -> 8521705.6 | E22: =E7*'Trafic mens2026'!P1075 -> 9907007.2 | F22: =(E22/D22-1)*100 -> 16.256153 | G22: =G24/'Trafic mens2026'!$Q$739 -> 8464099.2 | H22: =(G22/E22-1)*100 -> -14.564519 | I22: =I24/'Trafic mens2026'!$Q$739 -> 8464099.2 | J22: =(I22/E22-1)*100 -> -14.564519 | K22: =K24/'Trafic mens2026'!$Q$739 -> 8464099.2 | L22: =(K22/E22-1)*100 -> -14.564519 | M22: =M24/'Trafic mens2026'!$Q$739 -> 9141236.8 | N22: =(M22/K22-1)*100 -> 8.0001143 | O22: A partir de la part fin mai 2024 du transbordement conteneurisé appliqué au trafic dans le BP du TC2
C23: Brut | D23: ='Stats exo 2025brute'!F86 -> 9670336.6 | E23: =E27*'Trafic mens2026'!Q1240*2.2+E22 -> 11253829 | F23: =(E23/D23-1)*100 -> 16.374734 | G23: =G25+G26 -> 9616756.7 | H23: =(G23/E23-1)*100 -> -14.546799 | I23: =I25+I26 -> 9616756.7 | J23: =(I23/E23-1)*100 -> -14.546799 | K23: =K25+K26 -> 9616756.7 | L23: =(K23/E23-1)*100 -> -14.546799 | M23: =M25+M26 -> 10385884 | N23: =(M23/K23-1)*100 -> 7.99778 | O23: Somme des composantes.
B24: Transbordement conteneurisé | C24: Net | D24: =+D22*'Trafic mens2025'!Q739 -> 8434222.4 | E24: =E22*'Trafic mens2026'!$Q$739 -> 9810073.9 | F24: =(E24/D24-1)*100 -> 16.312725 | G24: =16*G29 -> 8381283.8 | H24: =(G24/$E24-1)*100 -> -14.564519 | I24: =16*I29 -> 8381283.8 | J24: =(I24/$E24-1)*100 -> -14.564519 | K24: =16*K29 -> 8381283.8 | L24: =(K24/$E24-1)*100 -> -14.564519 | M24: =16*M29 -> 9051796.1 | N24: =(M24/K24-1)*100 -> 8.0001143 | O24: On fait les hypothèses que tout le transbordement conteneurisé se fait au TC2 à partir de 2023 et qu'un conteneur plein d'un EVP contient en moyenne 17 tonnes de marchandises, sachant qu'on a un engagement de 285882,352941176 EVP pleins transbordés dans le BP du TC2 la 2ième année et 308752,94117647 EVP pleins transbordés la 3ième année.
C25: Brut | D25: =D23-D26 -> 9582853.4 | E25: =E23-E26 -> 11156895 | F25: =(E25/D25-1)*100 -> 16.425608 | G25: =G24+2.2*(G29+G30) -> 9533941.3 | H25: =(G25/$E25-1)*100 -> -14.546645 | I25: =I24+2.2*(I29+I30) -> 9533941.3 | J25: =(I25/$E25-1)*100 -> -14.546645 | K25: =K24+2.2*(K29+K30) -> 9533941.3 | L25: =(K25/$E25-1)*100 -> -14.546645 | M25: =M24+2.2*(M29+M30) -> 10296443 | N25: =(M25/K25-1)*100 -> 7.9977598 | O25: A partir de la prévision du trafic de transbordement conteneurisé net et de celle de la tare totale des conteneurs pleins transbordés.
B26: Transbordement non conteneurisé | C26: Net | D26: =D22-D24 -> 87483.203 | E26: =E22-E24 -> 96933.227 | F26: =(E26/D26-1)*100 -> 10.802101 | G26: =G22-G24 -> 82815.368 | H26: =(G26/$E26-1)*100 -> -14.564519 | I26: =I22-I24 -> 82815.368 | J26: =(I26/$E26-1)*100 -> -14.564519 | K26: =K22-K24 -> 82815.368 | L26: =(K26/$E26-1)*100 -> -14.564519 | M26: =M22-M24 -> 89440.692 | N26: =(M26/K26-1)*100 -> 8.0001143 | O26: Déduction
B27: Trafic global de conteneurs | C27: Teu total | D27: ='Trafic mens2025'!O1201 -> 1709308 | E27: =ANNUEL!N62 -> 1863897.7 | F27: =(E27/D27-1)*100 -> 9.0439914 | G27: =G28+G29+G30 -> 523935.22 | H27: =(G27/E27-1)*100 -> -71.890344 | I27: =I28+I29+I30 -> 523935.22 | J27: =(I27/E27-1)*100 -> -71.890344 | K27: =K28+K29+K30 -> 523935.22 | L27: =(K27/E27-1)*100 -> -71.890344 | M27: =M28+M29+M30 -> 565748.6 | N27: =(M27/K27-1)*100 -> 7.9806392 | O27: Somme des composantes.
C28: Teu non transbordés | D28: ='Trafic mens2025'!O1203+'Trafic mens2025'!O1204 -> 1187203 | E28: =E27-E29 -> 1254326.3 | F28: =(E28/D28-1)*100 -> 5.6539046 | H28: =(G28/E28-1)*100 -> -100 | J28: =(I28/E28-1)*100 -> -100 | L28: =(K28/E28-1)*100 -> -100 | N28: =(M28/K28-1)*100 -> #DIV/0! | O28: Modèle économétrique avec variables explicatives : dum1999, dum2003, dum2004, dum2005, dum2006, dum2009, dum2023, PIB CIV, PIB ML.
C29: Teu pleins transbordés | D29: ='Trafic mens2025'!O1318 -> 516271 | E29: =ANNUEL!N74*'Trafic mens2026'!Q1318 -> 609571.34 | F29: =(E29/SUM(D29)-1)*100 -> 18.071971 | G29: =REPARTITION!L46*1 -> 523830.24 | H29: =(G29/E29-1)*100 -> -14.065803 | I29: =G29 -> 523830.24 | J29: =(I29/E29-1)*100 -> -14.065803 | K29: =I29 -> 523830.24 | L29: =(K29/E29-1)*100 -> -14.065803 | M29: =REPARTITION!M46 -> 565737.26 | N29: =(M29/K29-1)*100 -> 8.0001143 | O29: Engagement de la 3ième année de trafic de conteneurs pleins transbordés en TEU dans le BP du TC2.
C30: Teu vides transbordés | D30: ='Trafic mens2025'!O1307 -> 5834 | E30: =ANNUEL!N74*'Trafic mens2026'!Q1307 -> 1580.7511 | F30: =(E30/SUM(D30)-1)*100 -> -72.904506 | G30: =REPARTITION!L47*0.1 -> 104.976 | H30: =(G30/E30-1)*100 -> -93.359106 | I30: =G30 -> 104.976 | J30: =(I30/E30-1)*100 -> -93.359106 | K30: =I30 -> 104.976 | L30: =(K30/E30-1)*100 -> -93.359106 | M30: =REPARTITION!M47*0.01 -> 11.33742 | N30: =(M30/K30-1)*100 -> -89.199989 | O30: 1% de l'engagement de la 3ième année de trafic de conteneurs vides transbordés en TEU dans le BP du TC2.
B31: Disclaimer : les prévisions actualisées de 2024 et les projections de 2025 et de 2026 présentées ci-dessus ont été faites sur la base des données réalisées à fin mai 2024 et les annoncé op de Juin à Sept. Elles seront donc caduques en fin d’année 2024 lorsque nous aurons la totalité données réalisées de 2024. Nous aurons des prévisions plus fiables en fin d’année ; celles-ci sont donc à considérer comme provisoires.
F34: BUSINESS PLAN TC2 | G34: 2025 | H34: 2026 | I34: 2027 | J34: 2028 | K34: 2029 | L34: 2030
E35: ENGAGEMENT | F35: TEU TRANSBO | G35: 486000 | H35: 524880 | I35: 566871 | J35: 612221 | K35: 661199 | L35: 714095
G36: 2025 | H36: 2026 | I36: 2027 | J36: 2028 | K36: 2029 | L36: 2030
F37: CNT PLEIN | G37: =+G35*0.97 -> 471420 | H37: =+H35*0.97 -> 509133.6 | I37: =+I35*0.97 -> 549864.87 | J37: =+J35*0.97 -> 593854.37 | K37: =+K35*0.97 -> 641363.03 | L37: =+L35*0.97 -> 692672.15
F38: TRANSBO CONT | G38: =+G37*17 -> 8014140 | H38: =+H37*17 -> 8655271.2 | I38: =+I37*17 -> 9347702.8 | J38: =+J37*17 -> 10095524 | K38: =+K37*17 -> 10903172 | L38: =+L37*17 -> 11775427
F39: TRANSBO | G39: =G38/'Trafic mens2026'!$Q$739 -> 8093327.6 | H39: =H38/'Trafic mens2026'!$Q$739 -> 8740793.8 | I39: =I38/'Trafic mens2026'!$Q$739 -> 9440067.3 | J39: =J38/'Trafic mens2026'!$Q$739 -> 10195278 | K39: =K38/'Trafic mens2026'!$Q$739 -> 11010906 | L39: =L38/'Trafic mens2026'!$Q$739 -> 11891779
G41: 8853864.2 | H41: 9296557.5 | I41: 9762975.2 | J41: 10252797 | K41: 10677022 | L41: 11097308

Sheet REPARTITION
A2: TRAFIC ESCALES DE NAVIRES (En Nbre)
B3: 2019 | C3: 2020 | D3: 2021 | E3: 2022 | F3: 2023 | G3: 2024 | H3: 2025 | I3: 2026
A4: ESCALES NAVIRES | B4: 2539 | C4: 2321 | D4: 2331 | E4: 2268 | F4: 2482 | G4: ='NON-RESPECT_ENGA_TRANSBO_TC2'!D4 -> 2748 | H4: ='NON-RESPECT_ENGA_TRANSBO_TC2'!E4 -> 2858.4504 | I4: ='NON-RESPECT_ENGA_TRANSBO_TC2'!K4 -> 458.81166
A5: Port de commerce | B5: 1690 | C5: 1626 | D5: 1700 | E5: 1707 | F5: 1998 | G5: ='NON-RESPECT_ENGA_TRANSBO_TC2'!D5 -> 2340 | H5: ='NON-RESPECT_ENGA_TRANSBO_TC2'!E5 -> 2446.3425 | I5: ='NON-RESPECT_ENGA_TRANSBO_TC2'!K5 -> 404.32518
A6: Port de pêche | B6: 849 | C6: 695 | D6: 631 | E6: 561 | F6: 484 | G6: ='NON-RESPECT_ENGA_TRANSBO_TC2'!D6 -> 408 | H6: ='NON-RESPECT_ENGA_TRANSBO_TC2'!E6 -> 412.10788 | I6: ='NON-RESPECT_ENGA_TRANSBO_TC2'!K6 -> 54.486479
A7: part | B7: =B5/B4 -> 0.66561638 | C7: =C5/C4 -> 0.7005601 | D7: =D5/D4 -> 0.72930073 | E7: =E5/E4 -> 0.7526455 | F7: =F5/F4 -> 0.80499597 | G7: =G5/G4 -> 0.85152838 | H7: =H5/H4 -> 0.85582822 | I7: =I5/I4 -> 0.88124435 | L7: 2026
B8: =B6/B4 -> 0.33438362 | C8: =C6/C4 -> 0.2994399 | D8: =D6/D4 -> 0.27069927 | E8: =E6/E4 -> 0.2473545 | F8: =F6/F4 -> 0.19500403 | G8: =G6/G4 -> 0.14847162 | H8: =H6/H4 -> 0.14417178 | I8: =I6/I4 -> 0.11875565 | K8: =H7+J9 -> 0.88124435 | L8: Part de 2023 des escales du Port de Commerce dans le trafic global d'escales+Moyenne de la variation absolue de la part des escales du Port de Commerce dans le trafic global d'escales sur les trois dernières années.
A9: V° des parts | C9: =C7-B7 -> 0.034943719 | D9: =D7-C7 -> 0.028740626 | E9: =E7-D7 -> 0.023344773 | F9: =F7-E7 -> 0.052350468 | G9: =G7-F7 -> 0.046532413 | H9: =H7-G7 -> 0.0042998366 | I9: =I7-H7 -> 0.025416125 | J9: =AVERAGE(G9:H9) -> 0.025416125 | K9: =1-K8 -> 0.11875565
C10: =C8-B8 -> -0.034943719 | D10: =D8-C8 -> -0.028740626 | E10: =E8-D8 -> -0.023344773 | F10: =F8-E8 -> -0.052350468 | G10: =G8-F8 -> -0.046532413 | H10: =H8-G8 -> -0.0042998366 | I10: =I8-H8 -> -0.025416125 | J10: =AVERAGE(G10:H10) -> -0.025416125
L11: 2027
G12: ='NON-RESPECT_ENGA_TRANSBO_TC2'!D7 -> 46935601 | J12: =AVERAGE(H9:I9) -> 0.014857981 | K12: =J12+I7 -> 0.89610233 | L12: Part de 2024 des escales du Port de Commerce dans le trafic global d'escales+Moyenne de la variation absolue de la part des escales du Port de Commerce dans le trafic global d'escales sur les trois dernières années.
K13: =1-K12 -> 0.10389767
B15: 2019 | C15: 2020 | D15: 2021 | E15: 2022 | F15: 2023 | G15: 2024 | H15: 2025 | I15: 2026
A16: TRAFIC GLOBAL | B16: 25738345 | C16: 25350923 | D16: 28313869 | E16: 28669102 | F16: 34704000 | G16: ='NON-RESPECT_ENGA_TRANSBO_TC2'!D7 -> 46935601 | H16: ='NON-RESPECT_ENGA_TRANSBO_TC2'!E7 -> 48477431 | I16: ='NON-RESPECT_ENGA_TRANSBO_TC2'!K7 -> 8464099.2
A17: ESCALES NAVIRES | B17: 2539 | C17: 2321 | D17: 2331 | E17: 2268 | F17: 2482 | G17: =G4 -> 2748 | H17: =H4 -> 2858.4504 | I17: =I4 -> 458.81166
A18: V ° TRAFIC | C18: =C16/B16-1 -> -0.015052352 | D18: =D16/C16-1 -> 0.11687725 | E18: =E16/D16-1 -> 0.012546276 | F18: =F16/E16-1 -> 0.2105018 | G18: =G16/F16-1 -> 0.35245508 | H18: =H16/G16-1 -> 0.032849895 | I18: =I16/G16-1 -> -0.81966569 | K18: 2026
A19: V ° ESCALES | C19: =C17/B17-1 -> -0.085860575 | D19: =D17/C17-1 -> 0.0043084877 | E19: =E17/D17-1 -> -0.027027027 | F19: =F17/E17-1 -> 0.094356261 | G19: =G17/F17-1 -> 0.10717164 | H19: =H17/G17-1 -> 0.040193014 | I19: =I17/H17-1 -> -0.83948938 | J19: =H20+J22 -> 18447.873 | K19: Tonnage moyen de 2023+Moyenne de la variation absolue du tonnage moyen sur les deux dernières années
A20: tonnage moyen/navire | B20: =B16/B17 -> 10137.198 | C20: =C16/C17 -> 10922.414 | D20: =D16/D17 -> 12146.662 | E20: =E16/E17 -> 12640.698 | F20: =F16/F17 -> 13982.272 | G20: =G16/G17 -> 17079.913 | H20: =H16/H17 -> 16959.339 | I20: =I16/I17 -> 18447.873
C21: =C20/B20-1 -> 0.077458888 | D21: =D20/C20-1 -> 0.11208584 | E21: =E20/D20-1 -> 0.040672561 | F21: =F20/E20-1 -> 0.10613138 | G21: =G20/F20-1 -> 0.22154057 | H21: =H20/G20-1 -> -0.0070593811 | I21: =I20/H20-1 -> 0.087770725
C22: =C20-B20 -> 785.21607 | D22: =D20-C20 -> 1224.248 | E22: =E20-D20 -> 494.03585 | F22: =F20-E20 -> 1341.5747 | G22: =G20-F20 -> 3097.6407 | H22: =H20-G20 -> -120.57362 | I22: =I20-H20 -> 1488.5335 | J22: =AVERAGE(G22:H22) -> 1488.5335 | K22: =AVERAGE(G22:I22) -> 1488.5335
J24: =K22+I20 -> 19936.407 | K24: 2027
K25: Tonnage moyen de 2024+Moyenne de la variation absolue du tonnage moyen sur les deux dernières années
B27: 2019 | C27: 2020 | D27: 2021 | E27: 2022 | F27: 2023 | G27: 2024 | H27: 2025 | I27: 2026
A28: TRAFIC GLOBAL | B28: 25738345 | C28: 25350923 | D28: 28313869 | E28: 28669102 | F28: 34704000 | G28: =G16 -> 46935601 | H28: =H16 -> 48477431 | I28: =I16 -> 8464099.2
A29: Trafic conteneurs en tonne | B29: 7532453 | C29: 8102939.2 | D29: 8515382.1 | E29: 8868123.4 | F29: 13642884 | G29: ='Trafic mens2025'!O1106 -> 19566896 | H29: =H16*'Trafic mens2026'!Q1106 -> 21334986 | I29: =I16*'Trafic mens2026'!Q1106 -> 3725062.1
A30: Trafic conteneurs en TEU | B30: 730827 | C30: 760149 | D30: 787314 | E30: 840426 | F30: 1238195 | G30: ='NON-RESPECT_ENGA_TRANSBO_TC2'!D27 -> 1709308 | H30: ='NON-RESPECT_ENGA_TRANSBO_TC2'!E27 -> 1863897.7 | I30: ='NON-RESPECT_ENGA_TRANSBO_TC2'!K27 -> 523935.22
A31: Conteneurs vides | B31: 192377 | C31: 183895 | D31: 163318 | E31: 193529 | F31: 313937 | G31: ='Trafic mens2025'!O1203 -> 397030 | H31: =H30-H33 -> 1254326.3 | I31: =I30-I33 -> 104.976
A32: Conteneurs pleins | B32: 538450 | C32: 576230 | D32: 623996 | E32: 632794 | F32: 677720 | G32: ='Trafic mens2025'!O1204 -> 790173
A33: Conteneurs transbordés | B33: 13217 | C33: 18383 | D33: 16891 | E33: 14103 | F33: 245752 | G33: ='NON-RESPECT_ENGA_TRANSBO_TC2'!D29 -> 516271 | H33: ='NON-RESPECT_ENGA_TRANSBO_TC2'!E29 -> 609571.34 | I33: ='NON-RESPECT_ENGA_TRANSBO_TC2'!K29 -> 523830.24
A34: Taux de conteneurisation | B34: =B29/B28 -> 0.29265491 | C34: =C29/C28 -> 0.31963094 | D34: =D29/D28 -> 0.30074951 | E34: =E29/E28 -> 0.30932686 | F34: =F29/F28 -> 0.39312138 | G34: =G29/G28 -> 0.41688816 | H34: =H29/H28 -> 0.44010143 | I34: =I29/I28 -> 0.44010143 | J34: =AVERAGE(C34:H34) -> 0.36330304
A35: part tonne | B35: =B29/B28 -> 0.29265491 | C35: =C29/C28 -> 0.31963094 | D35: =D29/D28 -> 0.30074951 | E35: =E29/E28 -> 0.30932686 | F35: =F29/F28 -> 0.39312138 | G35: =G29/G28 -> 0.41688816 | H35: =H29/H28 -> 0.44010143 | I35: =I29/I28 -> 0.44010143
A37: Part | B37: =B31/B$30 -> 0.26323193 | C37: =C31/C$30 -> 0.24191968 | D37: =D31/D$30 -> 0.20743693 | E37: =E31/E$30 -> 0.23027488 | F37: =F31/F$30 -> 0.25354407 | G37: =G31/G$30 -> 0.23227528 | H37: =H31/H$30 -> 0.67295879 | I37: =I31/I$30 -> 0.00020036065
B38: =B32/B$30 -> 0.73676807 | C38: =C32/C$30 -> 0.75804875 | D38: =D32/D$30 -> 0.79256307 | E38: =E32/E$30 -> 0.75294434 | F38: =F32/F$30 -> 0.54734513
B39: =B33/B$30 -> 0.018084991 | C39: =C33/C$30 -> 0.024183417 | D39: =D33/D$30 -> 0.021453956 | E39: =E33/E$30 -> 0.016780775 | F39: =F33/F$30 -> 0.19847601 | G39: =G33/G$30 -> 0.30203509 | H39: =H33/H$30 -> 0.32704121 | I39: =I33/I$30 -> 0.99979964
C40: =C33-B33 -> 5166 | D40: =D33-C33 -> -1492 | E40: =E33-D33 -> -2788 | F40: =F33-E33 -> 231649 | G40: =G33-F33 -> 270519 | H40: =H33-G33 -> 93300.343 | I40: =I33-G33 -> 7559.24 | K40: 2024 | L40: 2025
C41: =C33/B33-1 -> 0.39086026 | D41: =D33/C33-1 -> -0.081161943 | E41: =E33/D33-1 -> -0.16505832 | F41: =F33/E33-1 -> 16.425512 | G41: =G33/F33-1 -> 1.1007805 | H41: =H33/G33-1 -> 0.18071971 | I41: =I33/G33-1 -> 0.014642 | K41: Taux de respect de l'engagement de transbo
A42: Engament de transb | G42: 450000 | H42: 486000 | I42: 524880 | J42: plein | K42: ='NON-RESPECT_ENGA_TRANSBO_TC2'!D29/O46 -> 1.2747432 | L42: ='NON-RESPECT_ENGA_TRANSBO_TC2'!E29/K46 -> 1.2567756
J43: vide | K43: ='NON-RESPECT_ENGA_TRANSBO_TC2'!D30/O47 -> 0.12964444 | L43: ='NON-RESPECT_ENGA_TRANSBO_TC2'!E30/K47 -> 1.6262872
B44: 2019 | C44: 2020 | D44: 2021 | E44: 2022 | F44: 2023 | G44: 2024 | H44: 2025 | I44: 2026 | K44: Engagement transbo | P44: REALISE FIN AOUT
A45: TRAFIC GLOBAL | B45: 25738345 | C45: 25350923 | D45: 28313869 | E45: 28669102 | F45: 34704000 | G45: =G16 -> 46935601 | H45: =H16 -> 48477431 | I45: =I16 -> 8464099.2 | K45: 2025 | L45: 2026 | M45: 2027 | O45: 2024 | P45: PART 2024 | Q45: PART 2025
...

Sheet ANNUEL
G1: PREVISIONS
A2: TRAFIC ESCALES DE NAVIRES (En Nbre)
B4: Janv. | C4: Févr. | D4: Mars | E4: Avril | F4: Mai | G4: Juin | H4: Juil. | I4: Août | J4: Sept. | K4: Oct. | L4: Nov. | M4: Déc. | N4: Total
A5: Réalisé 2025 | B5: ='CALC. PREV'!B5 -> 246 | C5: ='CALC. PREV'!C5 -> 237 | D5: ='CALC. PREV'!D5 -> 244 | E5: ='CALC. PREV'!E5 -> 220 | F5: ='CALC. PREV'!F5 -> 247 | G5: ='CALC. PREV'!G5 -> 214 | H5: ='CALC. PREV'!H5 -> 212 | I5: ='CALC. PREV'!I5 -> 227 | ... M5: ='CALC. PREV'!M5 -> 243 | N5: =SUM(B5:M5) -> 2748
A6: Réalisé 2026 | B6: ='CALC. PREV'!B6 -> 266 | C6: ='CALC. PREV'!C6 -> 213 | D6: ='CALC. PREV'!D6 -> 262 | E6: ='CALC. PREV'!E6 -> 237 | F6: ='CALC. PREV'!F6 -> 221 | G6: ='CALC. PREV'!G6 -> 224 | H6: ='CALC. PREV'!H6 -> 227 | I6: ='CALC. PREV'!I11 -> 231.70403 | J6: ='CALC. PREV'!J11 -> 232.16421 | K6: ='CALC. PREV'!K11 -> 243.2087 | L6: ='CALC. PREV'!L11 -> 243.66888 | M6: ='CALC. PREV'!M11 -> 257.70458 | N6: =SUM(B6:M6) -> 2858.4504
A7: Variation 2026/2025 | B7: =+B6/B5-1 -> 0.081300813 | C7: =+C6/C5-1 -> -0.10126582 | D7: =+D6/D5-1 -> 0.073770492 | E7: =+E6/E5-1 -> 0.077272727 | F7: =+F6/F5-1 -> -0.10526316 | G7: =+G6/G5-1 -> 0.046728972 | H7: =+H6/H5-1 -> 0.070754717 | I7: =+I6/I5-1 -> 0.02072259 | ... M7: =+M6/M5-1 -> 0.060512671 | N7: =N6/N5-1 -> 0.040193014
A8: Prévision 2026 | B8: ='CALC. PREV'!B8 -> 237.35673 | C8: ='CALC. PREV'!C8 -> 219.21909 | D8: ='CALC. PREV'!D8 -> 228.62379 | E8: ='CALC. PREV'!E8 -> 227.28026 | F8: ='CALC. PREV'!F8 -> 238.02849 | G8: ='CALC. PREV'!G8 -> 218.09948 | H8: ='CALC. PREV'!H8 -> 237.35673 | I8: ='CALC. PREV'!I8 -> 225.48889 | ... M8: ='CALC. PREV'!M8 -> 250.79202 | N8: =SUM(B8:M8) -> 2782
A9: Variation (réalisé/prévu) | B9: =+B6/B8-1 -> 0.12067604 | C9: =+C6/C8-1 -> -0.0283693 | D9: =+D6/D8-1 -> 0.14598746 | E9: =+E6/E8-1 -> 0.04276542 | F9: =+F6/F8-1 -> -0.071539726 | G9: =+G6/G8-1 -> 0.027054237 | H9: =+H6/H8-1 -> -0.043633601 | I9: =+I6/I8-1 -> 0.027562934 | ... N9: =+N6/N8-1 -> 0.027480374
A14: TRAFIC GLOBAL (En tonne)
B16: Janv. | C16: Févr. | D16: Mars | E16: Avril | F16: Mai | G16: Juin | H16: Juil. | I16: Août | J16: Sept. | K16: Oct. | L16: Nov. | M16: Déc. | N16: Total
A17: Réalisé 2025 | B17: ='CALC. PREV'!B17 -> 3615145.5 | C17: ='CALC. PREV'!C17 -> 3783743.2 | D17: ='CALC. PREV'!D17 -> 3803233.9 | E17: ='CALC. PREV'!E17 -> 3843719 | F17: ='CALC. PREV'!F17 -> 4162238.8 | G17: ='CALC. PREV'!G17 -> 3625573.8 | H17: ='CALC. PREV'!H17 -> 4135296.2 | I17: ='CALC. PREV'!I17 -> 4273333.7 | ... M17: ='CALC. PREV'!M17 -> 4370330.8 | N17: =SUM(B17:M17) -> 46935601
A18: Réalisé 2026 | B18: ='CALC. PREV'!B18 -> 4130728.9 | C18: ='CALC. PREV'!C18 -> 3878339.6 | D18: ='CALC. PREV'!D18 -> 4262772.5 | E18: ='CALC. PREV'!E18 -> 4259824.9 | F18: ='CALC. PREV'!F18 -> 3832711.4 | G18: ='CALC. PREV'!G18 -> 3542274 | H18: ='CALC. PREV'!H18 -> 4113691 | I18: ='CALC. PREV'!I23 -> 4098176.8 | J18: ='CALC. PREV'!J23 -> 4021955.5 | K18: ='CALC. PREV'!K23 -> 4023031.9 | L18: ='CALC. PREV'!L23 -> 4061397.2 | M18: ='CALC. PREV'!M23 -> 4252527 | N18: =SUM(B18:M18) -> 48477431
A19: Variation 2026/2025 | B19: =B18/B17-1 -> 0.1426176 | C19: =C18/C17-1 -> 0.025000759 | D19: =D18/D17-1 -> 0.12082838 | E19: =E18/E17-1 -> 0.10825607 | F19: =F18/F17-1 -> -0.079170702 | G19: =G18/G17-1 -> -0.022975623 | H19: =H18/H17-1 -> -0.0052245722 | I19: =I18/I17-1 -> -0.040988355 | ... N19: =N18/N17-1 -> 0.032849895
A20: Prévision 2026 | B20: ='CALC. PREV'!B20 -> 3884471.7 | C20: ='CALC. PREV'!C20 -> 3932456.3 | D20: ='CALC. PREV'!D20 -> 4050445 | E20: ='CALC. PREV'!E20 -> 4263577.4 | F20: ='CALC. PREV'!F20 -> 4463003.4 | G20: ='CALC. PREV'!G20 -> 3920762 | H20: ='CALC. PREV'!H20 -> 4412909.2 | I20: ='CALC. PREV'!I20 -> 4221437.4 | ... M20: ='CALC. PREV'!M20 -> 4380429.9 | N20: =SUM(B20:M20) -> 50000000
A21: Variation (réalisé/prévu) | B21: =+B18/B20-1 -> 0.063395282 | C21: =+C18/C20-1 -> -0.013761557 | D21: =+D18/D20-1 -> 0.052420776 | E21: =+E18/E20-1 -> -0.00088013217 | F21: =+F18/F20-1 -> -0.14122597 | G21: =+G18/G20-1 -> -0.096534299 | H21: =+H18/H20-1 -> -0.067805202 | I21: =+I18/I20-1 -> -0.029198729 | ... N21: =+N18/N20-1 -> -0.030451387
A24: TRAFIC NATIONAL (En tonne)
B26: Janv. | C26: Févr. | D26: Mars | E26: Avril | F26: Mai | G26: Juin | H26: Juil. | I26: Août | J26: Sept. | K26: Oct. | L26: Nov. | M26: Déc. | N26: Total
A27: Réalisé 2025 | B27: ='CALC. PREV'!B29 -> 2475424.4 | C27: ='CALC. PREV'!C29 -> 2632090.6 | D27: ='CALC. PREV'!D29 -> 2741840 | E27: ='CALC. PREV'!E29 -> 2755337.1 | F27: ='CALC. PREV'!F29 -> 2951913.5 | G27: ='CALC. PREV'!G29 -> 2637505.8 | H27: ='CALC. PREV'!H29 -> 2991471.2 | I27: ='CALC. PREV'!I29 -> 3244153.4 | ... M27: ='CALC. PREV'!M29 -> 3241081.3 | N27: =SUM(B27:M27) -> 34475188
A28: Réalisé 2026 | B28: ='CALC. PREV'!B30 -> 3010311.1 | C28: ='CALC. PREV'!C30 -> 2680517.5 | D28: ='CALC. PREV'!D30 -> 2982124.4 | E28: ='CALC. PREV'!E30 -> 2992704.5 | F28: ='CALC. PREV'!F30 -> 2704573.1 | G28: ='CALC. PREV'!G30 -> 2499624.4 | H28: ='CALC. PREV'!H30 -> 2902847.8 | I28: ='CALC. PREV'!I35 -> 2891900.2 | J28: ='CALC. PREV'!J35 -> 2838114.2 | K28: ='CALC. PREV'!K35 -> 2838873.7 | L28: ='CALC. PREV'!L35 -> 2865946.4 | M28: ='CALC. PREV'!M35 -> 3000818.1 | N28: =SUM(B28:M28) -> 34208355
A29: Variation 2026/2025 | B29: =B28/B27-1 -> 0.21607878 | C29: =C28/C27-1 -> 0.018398639 | D29: =D28/D27-1 -> 0.087636215 | E29: =E28/E27-1 -> 0.0861482 | F29: =F28/F27-1 -> -0.083789858 | G29: =G28/G27-1 -> -0.052277209 | H29: =H28/H27-1 -> -0.029625357 | I29: =I28/I27-1 -> -0.10858095 | ... N29: =N28/N27-1 -> -0.0077398451
A30: Prévision 2026 | B30: ='CALC. PREV'!B32 -> 2978791.2 | C30: ='CALC. PREV'!C32 -> 3018943.6 | D30: ='CALC. PREV'!D32 -> 3133339.8 | E30: ='CALC. PREV'!E32 -> 3288582.5 | F30: ='CALC. PREV'!F32 -> 3356974 | G30: ='CALC. PREV'!G32 -> 3033198.9 | H30: ='CALC. PREV'!H32 -> 3340623.7 | I30: ='CALC. PREV'!I32 -> 3151049 | ... M30: ='CALC. PREV'!M32 -> 3286409.4 | N30: =SUM(B30:M30) -> 38000000
A31: Variation (réalisé/prévu) | B31: =B28/B30-1 -> 0.010581441 | C31: =C28/C30-1 -> -0.11210087 | D31: =D28/D30-1 -> -0.048260124 | E31: =E28/E30-1 -> -0.089971285 | F31: =F28/F30-1 -> -0.19434196 | G31: =G28/G30-1 -> -0.17591148 | H31: =H28/H30-1 -> -0.13104615 | I31: =I28/I30-1 -> -0.08224209 | ... N31: =N28/N30-1 -> -0.099780122
A34: TRAFIC TRANSIT (En tonne)
B36: Janv. | C36: Févr. | D36: Mars | E36: Avril | F36: Mai | G36: Juin | H36: Juil. | I36: Août | J36: Sept. | K36: Oct. | L36: Nov. | M36: Déc. | N36: Total
A37: Réalisé 2025 | B37: ='CALC. PREV'!B41 -> 314537.4 | C37: ='CALC. PREV'!C41 -> 286803.71 | D37: ='CALC. PREV'!D41 -> 176694.61 | E37: ='CALC. PREV'!E41 -> 414105.37 | F37: ='CALC. PREV'!F41 -> 339987.51 | G37: ='CALC. PREV'!G41 -> 328865.23 | H37: ='CALC. PREV'!H41 -> 422541.96 | I37: ='CALC. PREV'!I41 -> 347369.04 | ... M37: ='CALC. PREV'!M41 -> 372025.64 | N37: =SUM(B37:M37) -> 3938707.5
A38: Réalisé 2026 | B38: ='CALC. PREV'!B42 -> 328973.76 | C38: ='CALC. PREV'!C42 -> 401703.41 | D38: ='CALC. PREV'!D42 -> 401523.57 | E38: ='CALC. PREV'!E42 -> 355342.07 | F38: ='CALC. PREV'!F42 -> 344872.82 | G38: ='CALC. PREV'!G42 -> 318738.85 | H38: ='CALC. PREV'!H42 -> 370155.77 | I38: ='CALC. PREV'!I47 -> 368759.78 | J38: ='CALC. PREV'!J47 -> 361901.27 | K38: ='CALC. PREV'!K47 -> 361998.13 | L38: ='CALC. PREV'!L47 -> 365450.3 | M38: ='CALC. PREV'!M47 -> 382648.42 | N38: =SUM(B38:M38) -> 4362068.1
A39: Variation 2026/2025 | B39: =B38/B37-1 -> 0.045897111 | C39: =C38/C37-1 -> 0.40062137 | D39: =D38/D37-1 -> 1.2724154 | E39: =E38/E37-1 -> -0.14190422 | F39: =F38/F37-1 -> 0.014369097 | G39: =G38/G37-1 -> -0.030791884 | H39: =H38/H37-1 -> -0.12397868 | I39: =I38/I37-1 -> 0.061579281 | ... N39: =N38/N37-1 -> 0.1074872
A40: Prévision 2026 | B40: ='CALC. PREV'!B44 -> 333625.4 | C40: ='CALC. PREV'!C44 -> 314922.53 | D40: ='CALC. PREV'!D44 -> 322336.88 | E40: ='CALC. PREV'!E44 -> 354146.32 | F40: ='CALC. PREV'!F44 -> 385727.21 | G40: ='CALC. PREV'!G44 -> 264748.61 | H40: ='CALC. PREV'!H44 -> 347008.37 | I40: ='CALC. PREV'!I44 -> 331416.55 | ... M40: ='CALC. PREV'!M44 -> 337476.09 | N40: =SUM(B40:M40) -> 4000000
A41: Variation (réalisé/prévu) | B41: =B38/B40-1 -> -0.013942713 | C41: =C38/C40-1 -> 0.27556264 | D41: =D38/D40-1 -> 0.24566438 | E41: =E38/E40-1 -> 0.0033764263 | F41: =F38/F40-1 -> -0.10591523 | G41: =G38/G40-1 -> 0.20393024 | H41: =H38/H40-1 -> 0.066705568 | I41: =I38/I40-1 -> 0.11267763 | ... N41: =N38/N40-1 -> 0.090517035
A46: TRAFIC TRANSBORDEMENT (En tonne)
B48: Janv. | C48: Févr. | D48: Mars | E48: Avril | F48: Mai | G48: Juin | H48: Juil. | I48: Août | J48: Sept. | K48: Oct. | L48: Nov. | M48: Déc. | N48: Total
A49: Réalisé 2025 | B49: ='CALC. PREV'!B53 -> 825183.71 | C49: ='CALC. PREV'!C53 -> 864848.88 | D49: ='CALC. PREV'!D53 -> 884699.35 | E49: ='CALC. PREV'!E53 -> 674276.46 | F49: ='CALC. PREV'!F53 -> 870337.78 | G49: ='CALC. PREV'!G53 -> 659202.76 | H49: ='CALC. PREV'!H53 -> 721282.98 | I49: ='CALC. PREV'!I53 -> 681811.3 | ... M49: ='CALC. PREV'!M53 -> 757223.89 | N49: =SUM(B49:M49) -> 8521705.6
A50: Réalisé 2026 | B50: ='CALC. PREV'!B54 -> 791444.04 | C50: ='CALC. PREV'!C54 -> 796118.75 | D50: ='CALC. PREV'!D54 -> 879124.5 | E50: ='CALC. PREV'!E54 -> 911778.32 | F50: ='CALC. PREV'!F54 -> 783265.51 | G50: ='CALC. PREV'!G54 -> 723910.77 | H50: ='CALC. PREV'!H54 -> 840687.42 | I50: ='CALC. PREV'!I59 -> 837516.89 | J50: ='CALC. PREV'!J59 -> 821940.05 | K50: ='CALC. PREV'!K59 -> 822160.03 | L50: ='CALC. PREV'!L59 -> 830000.5 | M50: ='CALC. PREV'!M59 -> 869060.39 | N50: =SUM(B50:M50) -> 9907007.2
A51: Variation 2026/2025 | B51: =B50/B49-1 -> -0.040887467 | C51: =C50/C49-1 -> -0.07947068 | D51: =D50/D49-1 -> -0.0063013983 | E51: =E50/E49-1 -> 0.35223217 | F51: =F50/F49-1 -> -0.10004422 | G51: =G50/G49-1 -> 0.098161004 | H51: =H50/H49-1 -> 0.16554452 | I51: =I50/I49-1 -> 0.22837051 | ... N51: =N50/N49-1 -> 0.16256153
A52: Prévision 2026 | B52: ='CALC. PREV'!B56 -> 553513.88 | C52: ='CALC. PREV'!C56 -> 588297 | D52: ='CALC. PREV'!D56 -> 577033.46 | E52: ='CALC. PREV'!E56 -> 599164.39 | F52: ='CALC. PREV'!F56 -> 719942.5 | G52: ='CALC. PREV'!G56 -> 625474.3 | H52: ='CALC. PREV'!H56 -> 732235.3 | I52: ='CALC. PREV'!I56 -> 760823.4 | ... M52: ='CALC. PREV'!M56 -> 776325.37 | N52: =SUM(B52:M52) -> 8000000
A53: Variation (réalisé/prévu) | B53: =B50/B52-1 -> 0.429854 | C53: =C50/C52-1 -> 0.35325992 | D53: =D50/D52-1 -> 0.52352432 | E53: =E50/E52-1 -> 0.52174984 | F53: =F50/F52-1 -> 0.087955652 | G53: =G50/G52-1 -> 0.15737892 | H53: =H50/H52-1 -> 0.14811103 | I53: =I50/I52-1 -> 0.10080328 | ... N53: =N50/N52-1 -> 0.2383759
A58: TRAFIC CONTENEURS (En TEU)
B60: Janv. | C60: Févr. | D60: Mars | E60: Avril | F60: Mai | G60: Juin | H60: Juil. | I60: Août | J60: Sept. | K60: Oct. | L60: Nov. | M60: Déc. | N60: Total
A61: Réalisé 2025 | B61: ='CALC. PREV'!B65 -> 158014 | C61: ='CALC. PREV'!C65 -> 138758 | D61: ='CALC. PREV'!D65 -> 150740 | E61: ='CALC. PREV'!E65 -> 141918 | F61: ='CALC. PREV'!F65 -> 157734 | G61: ='CALC. PREV'!G65 -> 130245 | H61: ='CALC. PREV'!H65 -> 134863 | I61: ='CALC. PREV'!I65 -> 148944 | ... M61: ='CALC. PREV'!M65 -> 148531 | N61: =SUM(B61:M61) -> 1709308
A62: Réalisé 2026 | B62: ='CALC. PREV'!B66 -> 162428 | C62: ='CALC. PREV'!C66 -> 147867 | D62: ='CALC. PREV'!D66 -> 167378 | E62: ='CALC. PREV'!E66 -> 162680 | F62: ='CALC. PREV'!F66 -> 146795.47 | G62: ='CALC. PREV'!G66 -> 135671.52 | H62: ='CALC. PREV'!H66 -> 157557.18 | I62: ='CALC. PREV'!I71 -> 156962.98 | J62: ='CALC. PREV'!J71 -> 154043.65 | K62: ='CALC. PREV'!K71 -> 154084.88 | L62: ='CALC. PREV'!L71 -> 155554.3 | M62: ='CALC. PREV'!M71 -> 162874.69 | N62: =SUM(B62:M62) -> 1863897.7
...

Sheet CALC. PREV
D1: Annoncé DOMSE
A2: TRAFIC ESCALES DE NAVIRES (En Nbre)
N3: Total/Moyenne
B4: Janv. | C4: Févr. | D4: Mars | E4: Avril | F4: Mai | G4: Juin | H4: Juil. | I4: Août | J4: Sept. | K4: Oct. | L4: Nov. | M4: Déc.
A5: Réalisé 2025 | B5: ='Trafic mens2025'!C21 -> 246 | C5: ='Trafic mens2025'!D21 -> 237 | D5: ='Trafic mens2025'!E21 -> 244 | E5: ='Trafic mens2025'!F21 -> 220 | F5: ='Trafic mens2025'!G21 -> 247 | G5: ='Trafic mens2025'!H21 -> 214 | H5: ='Trafic mens2025'!I21 -> 212 | I5: ='Trafic mens2025'!J21 -> 227 | ... M5: ='Trafic mens2025'!N21 -> 243 | N5: =SUM(B5:M5) -> 2748
A6: Réalisé 2026 | B6: ='Trafic mens2026'!C21 -> 266 | C6: ='Trafic mens2026'!D21 -> 213 | D6: ='Trafic mens2026'!E21 -> 262 | E6: ='Trafic mens2026'!F21 -> 237 | F6: =+'Trafic mens2026'!Y21 -> 221 | G6: =+'Trafic mens2026'!Z21 -> 224 | H6: =+'Trafic mens2026'!AA21 -> 227 | I6: =+'Trafic mens2026'!AB21 -> 0 | J6: =+'Trafic mens2026'!AC21 -> 0 | K6: =+'Trafic mens2026'!AD21 -> 0 | L6: =+'Trafic mens2026'!AE21 -> 0 | M6: =+'Trafic mens2026'!AF21 -> 0 | N6: =AVERAGEIF(B6:M6, "<>0") -> 235.71429 | O6: moy
A7: Variation 2026/2025 | B7: =+B6/B5 -> 1.0813008 | C7: =+C6/C5 -> 0.89873418 | D7: =+D6/D5 -> 1.0737705 | E7: =+E6/E5 -> 1.0772727 | F7: =+F6/F5 -> 0.89473684 | G7: =+G6/G5 -> 1.046729 | H7: =+H6/H5 -> 1.0707547 | I7: =+I6/I5 -> 0 | ... M7: =+M6/M5 -> 0 | N7: =AVERAGEIF(B7:M7, "<>0") -> 1.0204712 | O7: moy
A8: Prévision 2026 | B8: =COEFFICIENTS_SAISONNIERS_2026!C14 -> 237.35673 | C8: =COEFFICIENTS_SAISONNIERS_2026!D14 -> 219.21909 | D8: =COEFFICIENTS_SAISONNIERS_2026!E14 -> 228.62379 | E8: =COEFFICIENTS_SAISONNIERS_2026!F14 -> 227.28026 | F8: =COEFFICIENTS_SAISONNIERS_2026!G14 -> 238.02849 | G8: =COEFFICIENTS_SAISONNIERS_2026!H14 -> 218.09948 | H8: =COEFFICIENTS_SAISONNIERS_2026!I14 -> 237.35673 | I8: =COEFFICIENTS_SAISONNIERS_2026!J14 -> 225.48889 | ... M8: =COEFFICIENTS_SAISONNIERS_2026!N14 -> 250.79202 | N8: =SUM(B8:M8) -> 2782
A9: Variation (réalisé/prévu) | B9: =+B6/B8 -> 1.120676 | C9: =+C6/C8 -> 0.9716307 | D9: =+D6/D8 -> 1.1459875 | E9: =+E6/E8 -> 1.0427654 | F9: =+F6/F8 -> 0.92846027 | G9: =+G6/G8 -> 1.0270542 | H9: =+H6/H8 -> 0.9563664 | I9: =+I6/I8 -> 0 | ... M9: =+M6/M8 -> 0 | N9: =AVERAGEIF(B9:M9, "<>0") -> 1.0275629 | O9: moy
B10: Sur la base du réalisé | I10: =I5*$N7 -> 231.64697 | J10: =J5*$N7 -> 213.27849 | K10: =K5*$N7 -> 225.52415 | L10: =L5*$N7 -> 232.66744 | M10: =M5*$N7 -> 247.97451 | N10: =SUM(B6:M6)+SUM(E10:M10) -> 2801.0916
B11: Correction des prévisions | I11: =I8*$N9 -> 231.70403 | J11: =J8*$N9 -> 232.16421 | K11: =K8*$N9 -> 243.2087 | L11: =L8*$N9 -> 243.66888 | M11: =M8*$N9 -> 257.70458 | N11: =SUM(B6:M6)+SUM(E11:M11) -> 2858.4504 | O11: Trafic de l'exercice
B12: Prévision avec les coefficients saisonniers | I12: =$N6*COEFFICIENTS_SAISONNIERS_2026!J13 -> 229.26364 | J12: =$N6*COEFFICIENTS_SAISONNIERS_2026!K13 -> 229.71898 | K12: =$N6*COEFFICIENTS_SAISONNIERS_2026!L13 -> 240.64713 | L12: =$N6*COEFFICIENTS_SAISONNIERS_2026!M13 -> 241.10247 | M12: =$N6*COEFFICIENTS_SAISONNIERS_2026!N13 -> 254.99034 | N12: =SUM(B6:M6)+SUM(E12:M12) -> 2845.7226
A14: TRAFIC GLOBAL (En tonne)
B16: Janv. | C16: Févr. | D16: Mars | E16: Avril | F16: Mai | G16: Juin | H16: Juil. | I16: Août | J16: Sept. | K16: Oct. | L16: Nov. | M16: Déc.
A17: Réalisé 2025 | B17: ='Trafic mens2025'!C73 -> 3615145.5 | C17: ='Trafic mens2025'!D73 -> 3783743.2 | D17: ='Trafic mens2025'!E73 -> 3803233.9 | E17: ='Trafic mens2025'!F73 -> 3843719 | F17: ='Trafic mens2025'!G73 -> 4162238.8 | G17: ='Trafic mens2025'!H73 -> 3625573.8 | H17: ='Trafic mens2025'!I73 -> 4135296.2 | I17: ='Trafic mens2025'!J73 -> 4273333.7 | ... M17: ='Trafic mens2025'!N73 -> 4370330.8 | N17: =SUM(B17:M17) -> 46935601
A18: Réalisé 2026 | B18: ='Trafic mens2026'!C73 -> 4130728.9 | C18: ='Trafic mens2026'!D73 -> 3878339.6 | D18: ='Trafic mens2026'!E73 -> 4262772.5 | E18: ='Trafic mens2026'!F73 -> 4259824.9 | F18: =+'Trafic mens2026'!Y74 -> 3832711.4 | G18: =+'Trafic mens2026'!Z74 -> 3542274 | H18: =+'Trafic mens2026'!AA74 -> 4113691 | I18: =+'Trafic mens2026'!AB74 -> 0 | J18: =+'Trafic mens2026'!AC74 -> 0 | K18: =+'Trafic mens2026'!AD74 -> 0 | L18: =+'Trafic mens2026'!AE74 -> 0 | M18: =+'Trafic mens2026'!AF74 -> 0 | N18: =AVERAGEIF(B18:M18, "<>0") -> 4002906 | O18: moy
A19: Variation 2026/2025 | B19: =B18/B17 -> 1.1426176 | C19: =C18/C17 -> 1.0250008 | D19: =D18/D17 -> 1.1208284 | E19: =E18/E17 -> 1.1082561 | F19: =F18/F17 -> 0.9208293 | G19: =G18/G17 -> 0.97702438 | H19: =H18/H17 -> 0.99477543 | I19: =I18/I17 -> 0 | ... M19: =M18/M17 -> 0 | N19: =AVERAGEIF(B19:M19, "<>0") -> 1.0413331 | O19: moy
A20: Prévision 2026 | B20: =COEFFICIENTS_SAISONNIERS_2026!C34 -> 3884471.7 | C20: =COEFFICIENTS_SAISONNIERS_2026!D34 -> 3932456.3 | D20: =COEFFICIENTS_SAISONNIERS_2026!E34 -> 4050445 | E20: =COEFFICIENTS_SAISONNIERS_2026!F34 -> 4263577.4 | F20: =COEFFICIENTS_SAISONNIERS_2026!G34 -> 4463003.4 | G20: =COEFFICIENTS_SAISONNIERS_2026!H34 -> 3920762 | H20: =COEFFICIENTS_SAISONNIERS_2026!I34 -> 4412909.2 | I20: =COEFFICIENTS_SAISONNIERS_2026!J34 -> 4221437.4 | ... M20: =COEFFICIENTS_SAISONNIERS_2026!N34 -> 4380429.9 | N20: =SUM(B20:M20) -> 50000000
A21: Variation (réalisé/prévu) | B21: =B18/B20 -> 1.0633953 | C21: =C18/C20 -> 0.98623844 | D21: =D18/D20 -> 1.0524208 | E21: =E18/E20 -> 0.99911987 | F21: =F18/F20 -> 0.85877403 | G21: =G18/G20 -> 0.9034657 | H21: =H18/H20 -> 0.9321948 | I21: =I18/I20 -> 0 | ... M21: =M18/M20 -> 0 | N21: =AVERAGEIF(B21:M21, "<>0") -> 0.97080127 | O21: moy | P21: TRAFIC GLOBAL | Q21: Trafic transit | R21: Trafic transbordement | S21: Trafic national
B22: Sur la base du réalisé | H22: =H17*$N19 -> 4306220.9 | I22: =I17*$N19 -> 4449964 | J22: =J17*$N19 -> 4005135.9 | K22: =K17*$N19 -> 3942998.4 | L22: =L17*$N19 -> 3842866.4 | M22: =M17*$N19 -> 4550970.3 | N22: =SUM(B18:M18)+SUM(E22:M22) -> 53118498 | P22: =SUM(Q22:S22) -> 53118498 | Q22: =N46 -> 4779678 | R22: =N58 -> 10855471 | S22: =N34 -> 37483349 | T22: Sur la base du réalisé
B23: Correction des prévisions | H23: =H20*$N21 -> 4284057.9 | I23: =I20*$N21 -> 4098176.8 | J23: =J20*$N21 -> 4021955.5 | K23: =K20*$N21 -> 4023031.9 | L23: =L20*$N21 -> 4061397.2 | M23: =M20*$N21 -> 4252527 | N23: =SUM(B18:M18)+SUM(E23:M23) -> 52761489 | O23: Trafic de l'exercice | P23: =SUM(Q23:S23) -> 52761489 | Q23: =N47 -> 4747553.8 | R23: =N59 -> 10782511 | S23: =N35 -> 37231423 | T23: Correction des prévisions
B24: Prévision avec les coefficients saisonniers | H24: =$N18*COEFFICIENTS_SAISONNIERS_2026!I33 -> 4239470.6 | I24: =$N18*COEFFICIENTS_SAISONNIERS_2026!J33 -> 4055524.2 | J24: =$N18*COEFFICIENTS_SAISONNIERS_2026!K33 -> 3980096.1 | K24: =$N18*COEFFICIENTS_SAISONNIERS_2026!L33 -> 3981161.3 | L24: =$N18*COEFFICIENTS_SAISONNIERS_2026!M33 -> 4019127.4 | M24: =$N18*COEFFICIENTS_SAISONNIERS_2026!N33 -> 4208267.9 | N24: =SUM(B18:M18)+SUM(E24:M24) -> 52503990 | P24: =SUM(Q24:S24) -> 52503990 | Q24: =N48 -> 4724383.7 | R24: =N60 -> 10729888 | S24: =N36 -> 37049718 | T24: Prévision avec les coefficients saisonniers
A26: TRAFIC NATIONAL (En tonne)
B28: Janv. | C28: Févr. | D28: Mars | E28: Avril | F28: Mai | G28: Juin | H28: Juil. | I28: Août | J28: Sept. | K28: Oct. | L28: Nov. | M28: Déc.
A29: Réalisé 2025 | B29: ='Trafic mens2025'!C718 -> 2475424.4 | C29: ='Trafic mens2025'!D718 -> 2632090.6 | D29: ='Trafic mens2025'!E718 -> 2741840 | E29: ='Trafic mens2025'!F718 -> 2755337.1 | F29: ='Trafic mens2025'!G718 -> 2951913.5 | G29: ='Trafic mens2025'!H718 -> 2637505.8 | H29: ='Trafic mens2025'!I718 -> 2991471.2 | I29: ='Trafic mens2025'!J718 -> 3244153.4 | ... M29: ='Trafic mens2025'!N718 -> 3241081.3 | N29: =SUM(B29:M29) -> 34475188
A30: Réalisé 2026 | B30: ='Trafic mens2026'!C1069 -> 3010311.1 | C30: ='Trafic mens2026'!D1069 -> 2680517.5 | D30: ='Trafic mens2026'!E1069 -> 2982124.4 | E30: ='Trafic mens2026'!F1069 -> 2992704.5 | F30: =+'Trafic mens2026'!Y1069 -> 2704573.1 | G30: =+'Trafic mens2026'!Z1069 -> 2499624.4 | H30: =+'Trafic mens2026'!AA1069 -> 2902847.8 | I30: =+'Trafic mens2026'!AB1069 -> 0 | J30: =+'Trafic mens2026'!AC1069 -> 0 | K30: =+'Trafic mens2026'!AD1069 -> 0 | L30: =+'Trafic mens2026'!AE1069 -> 0 | M30: =+'Trafic mens2026'!AF1069 -> 0 | N30: =AVERAGEIF(B30:M30, "<>0") -> 2824671.8 | O30: moy
A31: Variation 2026/2025 | B31: =B30/B29 -> 1.2160788 | C31: =C30/C29 -> 1.0183986 | D31: =D30/D29 -> 1.0876362 | E31: =E30/E29 -> 1.0861482 | F31: =F30/F29 -> 0.91621014 | G31: =G30/G29 -> 0.94772279 | H31: =H30/H29 -> 0.97037464 | I31: =I30/I29 -> 0 | ... M31: =M30/M29 -> 0 | N31: =AVERAGEIF(B31:M31, "<>0") -> 1.0346528 | O31: moy
A32: Prévision 2026 | B32: =COEFFICIENTS_SAISONNIERS_2026!C114 -> 2978791.2 | C32: =COEFFICIENTS_SAISONNIERS_2026!D114 -> 3018943.6 | D32: =COEFFICIENTS_SAISONNIERS_2026!E114 -> 3133339.8 | E32: =COEFFICIENTS_SAISONNIERS_2026!F114 -> 3288582.5 | F32: =COEFFICIENTS_SAISONNIERS_2026!G114 -> 3356974 | G32: =COEFFICIENTS_SAISONNIERS_2026!H114 -> 3033198.9 | H32: =COEFFICIENTS_SAISONNIERS_2026!I114 -> 3340623.7 | I32: =COEFFICIENTS_SAISONNIERS_2026!J114 -> 3151049 | ... M32: =COEFFICIENTS_SAISONNIERS_2026!N114 -> 3286409.4 | N32: =SUM(B32:M32) -> 38000000
A33: Variation (réalisé/prévu) | B33: =B30/B32 -> 1.0105814 | C33: =C30/C32 -> 0.88789913 | D33: =D30/D32 -> 0.95173988 | E33: =E30/E32 -> 0.91002872 | F33: =F30/F32 -> 0.80565804 | G33: =G30/G32 -> 0.82408852 | H33: =H30/H32 -> 0.86895385 | I33: =I30/I32 -> 0 | ... M33: =M30/M32 -> 0 | N33: =AVERAGEIF(B33:M33, "<>0") -> 0.89413566 | O33: moy
